<?xml version="1.0" encoding="utf-8"?>
<!-- This URDF was automatically created by SolidWorks to URDF Exporter! Originally created by Stephen Brawner (brawner@gmail.com) 
     Commit Version: 1.6.0-4-g7f85cfe  Build Version: 1.6.7995.38578
     For more information, please see http://wiki.ros.org/sw_urdf_exporter -->
<robot
  name="solar_panel_installation_robot">
  <link
    name="base_link">
    <inertial>
      <origin
        xyz="0.417820527753063 0.00767344897305333 0.894229262078614"
        rpy="0 0 0" />
      <mass
        value="1161.6695731136" />
      <inertia
        ixx="754.757010279649"
        ixy="57.9272256461836"
        ixz="-497.669268719649"
        iyy="1352.7304511101"
        iyz="36.0482654432731"
        izz="670.489604780939" />
    </inertial>
    <visual>
      <origin
        xyz="0 0 0"
        rpy="0 0 0" />
      <geometry>
        <mesh
          filename="package://spir_description/meshes/base_link.STL" />
      </geometry>
      <material
        name="">
        <color
          rgba="0.792156862745098 0.819607843137255 0.933333333333333 1" />
      </material>
    </visual>
    <collision>
      <origin
        xyz="0 0 0"
        rpy="0 0 0" />
      <geometry>
        <mesh
          filename="package://spir_description/meshes/base_link.STL" />
      </geometry>
    </collision>
  </link>
  <link
    name="Link_1">
    <inertial>
      <origin
        xyz="0.417820527753063 0.00767344897305333 0.615729262078614"
        rpy="0 0 0" />
      <mass
        value="1161.6695731136" />
      <inertia
        ixx="754.757010279649"
        ixy="57.9272256461836"
        ixz="-497.669268719649"
        iyy="1352.7304511101"
        iyz="36.0482654432731"
        izz="670.489604780939" />
    </inertial>
    <visual>
      <origin
        xyz="0 0 0"
        rpy="0 0 0" />
      <geometry>
        <mesh
          filename="package://spir_description/meshes/Link_1.STL" />
      </geometry>
      <material
        name="">
        <color
          rgba="0.752941176470588 0.752941176470588 0.752941176470588 1" />
      </material>
    </visual>
    <collision>
      <origin
        xyz="0 0 0"
        rpy="0 0 0" />
      <geometry>
        <mesh
          filename="package://spir_description/meshes/Link_1.STL" />
      </geometry>
    </collision>
  </link>
  <joint
    name="axis-0"
    type="revolute">
    <origin
      xyz="0 0 0.2785"
      rpy="0 0 0" />
    <parent
      link="base_link" />
    <child
      link="Link_1" />
    <axis
      xyz="0 0 1" />
    <limit
      lower="-3.1415"
      upper="3.1415"
      effort="10"
      velocity="10" />
  </joint>
  <link
    name="Link_2">
    <inertial>
      <origin
        xyz="0.0178205277530617 -0.126826551026947 0.292729262078616"
        rpy="0 0 0" />
      <mass
        value="1161.6695731136" />
      <inertia
        ixx="754.75701027965"
        ixy="57.9272256461836"
        ixz="-497.669268719649"
        iyy="1352.7304511101"
        iyz="36.0482654432731"
        izz="670.489604780939" />
    </inertial>
    <visual>
      <origin
        xyz="0 0 0"
        rpy="0 0 0" />
      <geometry>
        <mesh
          filename="package://spir_description/meshes/Link_2.STL" />
      </geometry>
      <material
        name="">
        <color
          rgba="0.792156862745098 0.819607843137255 0.933333333333333 1" />
      </material>
    </visual>
    <collision>
      <origin
        xyz="0 0 0"
        rpy="0 0 0" />
      <geometry>
        <mesh
          filename="package://spir_description/meshes/Link_2.STL" />
      </geometry>
    </collision>
  </link>
  <joint
    name="axis-1"
    type="revolute">
    <origin
      xyz="0.400000000000002 0.1345 0.322999999999998"
      rpy="0 0 0" />
    <parent
      link="Link_1" />
    <child
      link="Link_2" />
    <axis
      xyz="0 -1 0" />
    <limit
      lower="-3.1415"
      upper="3.1415"
      effort="10"
      velocity="10" />
  </joint>
  <link
    name="Link_3">
    <inertial>
      <origin
        xyz="0.017820527753075 -0.125826551026947 -0.907270737921407"
        rpy="0 0 0" />
      <mass
        value="1161.6695731136" />
      <inertia
        ixx="754.75701027965"
        ixy="57.9272256461836"
        ixz="-497.669268719649"
        iyy="1352.7304511101"
        iyz="36.0482654432731"
        izz="670.489604780939" />
    </inertial>
    <visual>
      <origin
        xyz="0 0 0"
        rpy="0 0 0" />
      <geometry>
        <mesh
          filename="package://spir_description/meshes/Link_3.STL" />
      </geometry>
      <material
        name="">
        <color
          rgba="0.792156862745098 0.819607843137255 0.933333333333333 1" />
      </material>
    </visual>
    <collision>
      <origin
        xyz="0 0 0"
        rpy="0 0 0" />
      <geometry>
        <mesh
          filename="package://spir_description/meshes/Link_3.STL" />
      </geometry>
    </collision>
  </link>
  <joint
    name="axis-2"
    type="revolute">
    <origin
      xyz="0 -0.00100000000000011 1.20000000000002"
      rpy="0 0 0" />
    <parent
      link="Link_2" />
    <child
      link="Link_3" />
    <axis
      xyz="0 1 0" />
    <limit
      lower="-3.1415"
      upper="3.1415"
      effort="10"
      velocity="10" />
  </joint>
  <link
    name="Link_4">
    <inertial>
      <origin
        xyz="-0.37671187560197 0.134173448973048 -1.1573774005734"
        rpy="0 0 0" />
      <mass
        value="1161.6695731136" />
      <inertia
        ixx="754.75701027965"
        ixy="57.9272256461836"
        ixz="-497.669268719649"
        iyy="1352.7304511101"
        iyz="36.0482654432731"
        izz="670.489604780939" />
    </inertial>
    <visual>
      <origin
        xyz="0 0 0"
        rpy="0 0 0" />
      <geometry>
        <mesh
          filename="package://spir_description/meshes/Link_4.STL" />
      </geometry>
      <material
        name="">
        <color
          rgba="0.792156862745098 0.819607843137255 0.933333333333333 1" />
      </material>
    </visual>
    <collision>
      <origin
        xyz="0 0 0"
        rpy="0 0 0" />
      <geometry>
        <mesh
          filename="package://spir_description/meshes/Link_4.STL" />
      </geometry>
    </collision>
  </link>
  <joint
    name="axis-3"
    type="revolute">
    <origin
      xyz="0.39453 -0.26 0.25011"
      rpy="0 0 0" />
    <parent
      link="Link_3" />
    <child
      link="Link_4" />
    <axis
      xyz="-1 0 -0.00027033" />
    <limit
      lower="-3.1415"
      upper="3.1415"
      effort="10"
      velocity="10" />
  </joint>
  <link
    name="Link_5">
    <inertial>
      <origin
        xyz="-1.62931203577944 0.302173448973054 -1.15771601461788"
        rpy="0 0 0" />
      <mass
        value="1161.6695731136" />
      <inertia
        ixx="754.75701027965"
        ixy="57.9272256461836"
        ixz="-497.669268719649"
        iyy="1352.7304511101"
        iyz="36.0482654432731"
        izz="670.489604780939" />
    </inertial>
    <visual>
      <origin
        xyz="0 0 0"
        rpy="0 0 0" />
      <geometry>
        <mesh
          filename="package://spir_description/meshes/Link_5.STL" />
      </geometry>
      <material
        name="">
        <color
          rgba="0.792156862745098 0.819607843137255 0.933333333333333 1" />
      </material>
    </visual>
    <collision>
      <origin
        xyz="0 0 0"
        rpy="0 0 0" />
      <geometry>
        <mesh
          filename="package://spir_description/meshes/Link_5.STL" />
      </geometry>
    </collision>
  </link>
  <joint
    name="axis-4"
    type="revolute">
    <origin
      xyz="1.2526 -0.168 0.00033861"
      rpy="0 0 0" />
    <parent
      link="Link_4" />
    <child
      link="Link_5" />
    <axis
      xyz="0 1 0" />
    <limit
      lower="-3.1415"
      upper="3.1415"
      effort="10"
      velocity="10" />
  </joint>
  <link
    name="Link_6">
    <inertial>
      <origin
        xyz="0.210890556634789 -0.00845239883053628 0.0149766824619597"
        rpy="0 0 0" />
      <mass
        value="44.7597449842918" />
      <inertia
        ixx="12.6343269644531"
        ixy="3.08204339707178E-05"
        ixz="-0.0230093907202383"
        iyy="9.98632078269346"
        iyz="7.80279190266377E-06"
        izz="2.7081397351032" />
    </inertial>
    <visual>
      <origin
        xyz="0 0 0"
        rpy="0 0 0" />
      <geometry>
        <mesh
          filename="package://spir_description/meshes/Link_6.STL" />
      </geometry>
      <material
        name="">
        <color
          rgba="0.752941176470588 0.752941176470588 0.752941176470588 1" />
      </material>
    </visual>
    <collision>
      <origin
        xyz="0 0 0"
        rpy="0 0 0" />
      <geometry>
        <mesh
          filename="package://spir_description/meshes/Link_6.STL" />
      </geometry>
    </collision>
  </link>
  <joint
    name="axis-5"
    type="revolute">
    <origin
      xyz="0.277 0.168 7.4881E-05"
      rpy="0 0 0" />
    <parent
      link="Link_5" />
    <child
      link="Link_6" />
    <axis
      xyz="-1 0 -0.00027033" />
    <limit
      lower="-3.1415"
      upper="3.1415"
      effort="10"
      velocity="10" />
  </joint>
  <link
    name="camera_optical_frame">
    <inertial>
      <origin
        xyz="-0.849173448973032 1.16227552217461 -2.15102494035099"
        rpy="0 0 0" />
      <mass
        value="1161.6695731136" />
      <inertia
        ixx="1352.7304511101"
        ixy="36.0326047225112"
        ixz="-57.9369684177753"
        iyy="670.758679708012"
        iyz="497.691975897366"
        izz="754.487935352575" />
    </inertial>
  </link>
  <joint
    name="Joint_camera"
    type="fixed">
    <origin
      xyz="0.2444 -0.715 0.0050661"
      rpy="-1.5705 0 -1.5708" />
    <parent
      link="Link_6" />
    <child
      link="camera_optical_frame" />
    <axis
      xyz="0 0 0" />
  </joint>
</robot>