<?xml version="1.0" encoding="utf-8"?>
<!-- This URDF was automatically created by SolidWorks to URDF Exporter! Originally created by Stephen Brawner (brawner@gmail.com) 
     Commit Version: 1.6.0-4-g7f85cfe  Build Version: 1.6.7995.38578
     For more information, please see http://wiki.ros.org/sw_urdf_exporter -->
<robot
  name="solar_panel_installation_robot">
  <link
    name="base_link">
    <inertial>
      <origin
        xyz="0.25699 0.0055449 0.72564"
        rpy="0 0 0" />
      <mass
        value="1366.3" />
      <inertia
        ixx="707.3"
        ixy="38.02"
        ixz="-378.4"
        iyy="1078.1"
        iyz="22.527"
        izz="452.46" />
    </inertial>
    <visual>
      <origin
        xyz="0 0 0"
        rpy="0 0 0" />
      <geometry>
        <mesh
          filename="package://spir_description/meshes/base_link.STL" />
      </geometry>
      <material
        name="">
        <color
          rgba="0.79216 0.81961 0.93333 1" />
      </material>
    </visual>
    <collision>
      <origin
        xyz="0 0 0"
        rpy="0 0 0" />
      <geometry>
        <mesh
          filename="package://spir_description/meshes/base_link.STL" />
      </geometry>
    </collision>
  </link>
  <link
    name="Link_1">
    <inertial>
      <origin
        xyz="0.25701 0.0055453 0.44714"
        rpy="0 0 0" />
      <mass
        value="1366.3" />
      <inertia
        ixx="707.3"
        ixy="38.02"
        ixz="-378.4"
        iyy="1078.1"
        iyz="22.527"
        izz="452.46" />
    </inertial>
    <visual>
      <origin
        xyz="0 0 0"
        rpy="0 0 0" />
      <geometry>
        <mesh
          filename="package://spir_description/meshes/Link_1.STL" />
      </geometry>
      <material
        name="">
        <color
          rgba="0.75294 0.75294 0.75294 1" />
      </material>
    </visual>
    <collision>
      <origin
        xyz="0 0 0"
        rpy="0 0 0" />
      <geometry>
        <mesh
          filename="package://spir_description/meshes/Link_1.STL" />
      </geometry>
    </collision>
  </link>
  <joint
    name="axis-1"
    type="revolute">
    <origin
      xyz="-1.7894E-05 0 0.2785"
      rpy="0 0 0" />
    <parent
      link="base_link" />
    <child
      link="Link_1" />
    <axis
      xyz="0 0 1" />
    <limit
      lower="-3.1415"
      upper="3.1415"
      effort="10"
      velocity="10" />
  </joint>
  <link
    name="Link_2">
    <inertial>
      <origin
        xyz="-0.14299 -0.12895 0.12414"
        rpy="0 0 0" />
      <mass
        value="1366.3" />
      <inertia
        ixx="707.3"
        ixy="38.02"
        ixz="-378.4"
        iyy="1078.1"
        iyz="22.527"
        izz="452.46" />
    </inertial>
    <visual>
      <origin
        xyz="0 0 0"
        rpy="0 0 0" />
      <geometry>
        <mesh
          filename="package://spir_description/meshes/Link_2.STL" />
      </geometry>
      <material
        name="">
        <color
          rgba="0.79216 0.81961 0.93333 1" />
      </material>
    </visual>
    <collision>
      <origin
        xyz="0 0 0"
        rpy="0 0 0" />
      <geometry>
        <mesh
          filename="package://spir_description/meshes/Link_2.STL" />
      </geometry>
    </collision>
  </link>
  <joint
    name="axis-2"
    type="revolute">
    <origin
      xyz="0.4 0.1345 0.323"
      rpy="0 0 0" />
    <parent
      link="Link_1" />
    <child
      link="Link_2" />
    <axis
      xyz="0 1 0" />
    <limit
      lower="-3.1415"
      upper="3.1415"
      effort="10"
      velocity="10" />
  </joint>
  <link
    name="Link_3">
    <inertial>
      <origin
        xyz="-0.14299 -0.15795 -1.0759"
        rpy="0 0 0" />
      <mass
        value="1366.3" />
      <inertia
        ixx="707.3"
        ixy="38.02"
        ixz="-378.4"
        iyy="1078.1"
        iyz="22.527"
        izz="452.46" />
    </inertial>
    <visual>
      <origin
        xyz="0 0 0"
        rpy="0 0 0" />
      <geometry>
        <mesh
          filename="package://spir_description/meshes/Link_3.STL" />
      </geometry>
      <material
        name="">
        <color
          rgba="0.79216 0.81961 0.93333 1" />
      </material>
    </visual>
    <collision>
      <origin
        xyz="0 0 0"
        rpy="0 0 0" />
      <geometry>
        <mesh
          filename="package://spir_description/meshes/Link_3.STL" />
      </geometry>
    </collision>
  </link>
  <joint
    name="axis-3"
    type="revolute">
    <origin
      xyz="0 0.029 1.2"
      rpy="0 0 0" />
    <parent
      link="Link_2" />
    <child
      link="Link_3" />
    <axis
      xyz="0 1 0" />
    <limit
      lower="-3.1415"
      upper="3.1415"
      effort="10"
      velocity="10" />
  </joint>
  <link
    name="Link_4">
    <inertial>
      <origin
        xyz="-0.53788 0.13205 -1.3258"
        rpy="0 0 0" />
      <mass
        value="1366.3" />
      <inertia
        ixx="707.1"
        ixy="38.026"
        ixz="-378.46"
        iyy="1078.1"
        iyz="22.516"
        izz="452.67" />
    </inertial>
    <visual>
      <origin
        xyz="0 0 0"
        rpy="0 0 0" />
      <geometry>
        <mesh
          filename="package://spir_description/meshes/Link_4.STL" />
      </geometry>
      <material
        name="">
        <color
          rgba="0.79216 0.81961 0.93333 1" />
      </material>
    </visual>
    <collision>
      <origin
        xyz="0 0 0"
        rpy="0 0 0" />
      <geometry>
        <mesh
          filename="package://spir_description/meshes/Link_4.STL" />
      </geometry>
    </collision>
  </link>
  <joint
    name="axis-4"
    type="revolute">
    <origin
      xyz="0.39453 -0.29 0.25011"
      rpy="0 -0.00027033 0" />
    <parent
      link="Link_3" />
    <child
      link="Link_4" />
    <axis
      xyz="-1 0 0" />
    <limit
      lower="-3.1415"
      upper="3.1415"
      effort="10"
      velocity="10" />
  </joint>
  <link
    name="Link_5">
    <inertial>
      <origin
        xyz="-1.7905 0.15265 -1.3324"
        rpy="0 0 0" />
      <mass
        value="1366.3" />
      <inertia
        ixx="707.1"
        ixy="-0.39813"
        ixz="-380.37"
        iyy="1076.2"
        iyz="-40.795"
        izz="454.52" />
    </inertial>
    <visual>
      <origin
        xyz="0 0 0"
        rpy="0 0 0" />
      <geometry>
        <mesh
          filename="package://spir_description/meshes/Link_5.STL" />
      </geometry>
      <material
        name="">
        <color
          rgba="0.79216 0.81961 0.93333 1" />
      </material>
    </visual>
    <collision>
      <origin
        xyz="0 0 0"
        rpy="0 0 0" />
      <geometry>
        <mesh
          filename="package://spir_description/meshes/Link_5.STL" />
      </geometry>
    </collision>
  </link>
  <joint
    name="axis-5"
    type="revolute">
    <origin
      xyz="1.2526 -0.15441 -0.015677"
      rpy="0.10118 0 0" />
    <parent
      link="Link_4" />
    <child
      link="Link_5" />
    <axis
      xyz="0 1 0" />
    <limit
      lower="-3.1415"
      upper="3.1415"
      effort="10"
      velocity="10" />
  </joint>
  <link
    name="Link_6">
    <inertial>
      <origin
        xyz="0.025 0.019999 0.07"
        rpy="0 0 0" />
      <mass
        value="3" />
      <inertia
        ixx="0.0325"
        ixy="-1.0944E-18"
        ixz="4.2054E-18"
        iyy="0.023125"
        iyz="2.0189E-07"
        izz="0.010625" />
    </inertial>
    <visual>
      <origin
        xyz="0 0 0"
        rpy="0 0 0" />
      <geometry>
        <mesh
          filename="package://spir_description/meshes/Link_6.STL" />
      </geometry>
      <material
        name="">
        <color
          rgba="1 1 1 1" />
      </material>
    </visual>
    <collision>
      <origin
        xyz="0 0 0"
        rpy="0 0 0" />
      <geometry>
        <mesh
          filename="package://spir_description/meshes/Link_6.STL" />
      </geometry>
    </collision>
  </link>
  <joint
    name="axis-6"
    type="revolute">
    <origin
      xyz="0.27697 0.1552 0.0039567"
      rpy="-0.10119 -0.014285 0" />
    <parent
      link="Link_5" />
    <child
      link="Link_6" />
    <axis
      xyz="-1 0 0" />
    <limit
      lower="-3.1415"
      upper="3.1415"
      effort="10"
      velocity="10" />
  </joint>
</robot>